2022-03-04 09:13:27,372 INFO    MainThread:3476583 [wandb_setup.py:_flush():75] Loading settings from /home/pxk/.config/wandb/settings
2022-03-04 09:13:27,373 INFO    MainThread:3476583 [wandb_setup.py:_flush():75] Loading settings from /home/pxk/CBREN/wandb/settings
2022-03-04 09:13:27,373 INFO    MainThread:3476583 [wandb_setup.py:_flush():75] Loading settings from environment variables: {}
2022-03-04 09:13:27,373 INFO    MainThread:3476583 [wandb_setup.py:_flush():75] Inferring run settings from compute environment: {'program_relpath': 'train_psnr_indication.py', 'program': 'train_psnr_indication.py'}
2022-03-04 09:13:27,373 INFO    MainThread:3476583 [wandb_init.py:_log_setup():386] Logging user logs to /home/pxk/CBREN/wandb/run-20220304_091327-22vdt3du/logs/debug.log
2022-03-04 09:13:27,374 INFO    MainThread:3476583 [wandb_init.py:_log_setup():387] Logging internal logs to /home/pxk/CBREN/wandb/run-20220304_091327-22vdt3du/logs/debug-internal.log
2022-03-04 09:13:27,374 INFO    MainThread:3476583 [wandb_init.py:init():420] calling init triggers
2022-03-04 09:13:27,374 INFO    MainThread:3476583 [wandb_init.py:init():427] wandb.init called with sweep_config: {}
config: {'lr_rate': 0.0001, 'epoch': 5000, 'batch_size': 16}
2022-03-04 09:13:27,375 INFO    MainThread:3476583 [wandb_init.py:init():471] starting backend
2022-03-04 09:13:27,375 INFO    MainThread:3476583 [backend.py:_multiprocessing_setup():101] multiprocessing start_methods=fork,spawn,forkserver, using: spawn
2022-03-04 09:13:27,383 INFO    MainThread:3476583 [backend.py:ensure_launched():219] starting backend process...
2022-03-04 09:13:27,387 INFO    MainThread:3476583 [backend.py:ensure_launched():225] started backend process with pid: 3476736
2022-03-04 09:13:27,388 INFO    MainThread:3476583 [wandb_init.py:init():480] backend started and connected
2022-03-04 09:13:27,390 INFO    MainThread:3476583 [wandb_init.py:init():550] updated telemetry
2022-03-04 09:13:27,402 INFO    MainThread:3476583 [wandb_init.py:init():581] communicating current version
2022-03-04 09:13:28,867 INFO    MainThread:3476583 [wandb_init.py:init():586] got version response 
2022-03-04 09:13:28,868 INFO    MainThread:3476583 [wandb_init.py:init():596] communicating run to backend with 30 second timeout
2022-03-04 09:13:29,053 ERROR   Thread-1  :3476583 [retry.py:__call__():126] Retry attempt failed:
Traceback (most recent call last):
  File "/home/pxk/anaconda3/envs/cxy/lib/python3.7/site-packages/urllib3/connectionpool.py", line 700, in urlopen
    self._prepare_proxy(conn)
  File "/home/pxk/anaconda3/envs/cxy/lib/python3.7/site-packages/urllib3/connectionpool.py", line 994, in _prepare_proxy
    conn.connect()
  File "/home/pxk/anaconda3/envs/cxy/lib/python3.7/site-packages/urllib3/connection.py", line 426, in connect
    tls_in_tls=tls_in_tls,
  File "/home/pxk/anaconda3/envs/cxy/lib/python3.7/site-packages/urllib3/util/ssl_.py", line 450, in ssl_wrap_socket
    sock, context, tls_in_tls, server_hostname=server_hostname
  File "/home/pxk/anaconda3/envs/cxy/lib/python3.7/site-packages/urllib3/util/ssl_.py", line 493, in _ssl_wrap_socket_impl
    return ssl_context.wrap_socket(sock, server_hostname=server_hostname)
  File "/home/pxk/anaconda3/envs/cxy/lib/python3.7/ssl.py", line 423, in wrap_socket
    session=session
  File "/home/pxk/anaconda3/envs/cxy/lib/python3.7/ssl.py", line 870, in _create
    self.do_handshake()
  File "/home/pxk/anaconda3/envs/cxy/lib/python3.7/ssl.py", line 1139, in do_handshake
    self._sslobj.do_handshake()
ssl.SSLError: [SSL: KRB5_S_TKT_NYV] unexpected eof while reading (_ssl.c:1091)

During handling of the above exception, another exception occurred:

Traceback (most recent call last):
  File "/home/pxk/anaconda3/envs/cxy/lib/python3.7/site-packages/requests/adapters.py", line 450, in send
    timeout=timeout
  File "/home/pxk/anaconda3/envs/cxy/lib/python3.7/site-packages/urllib3/connectionpool.py", line 786, in urlopen
    method, url, error=e, _pool=self, _stacktrace=sys.exc_info()[2]
  File "/home/pxk/anaconda3/envs/cxy/lib/python3.7/site-packages/urllib3/util/retry.py", line 592, in increment
    raise MaxRetryError(_pool, url, error or ResponseError(cause))
urllib3.exceptions.MaxRetryError: HTTPSConnectionPool(host='api.wandb.ai', port=443): Max retries exceeded with url: /graphql (Caused by SSLError(SSLError(1, '[SSL: KRB5_S_TKT_NYV] unexpected eof while reading (_ssl.c:1091)')))

During handling of the above exception, another exception occurred:

Traceback (most recent call last):
  File "/home/pxk/anaconda3/envs/cxy/lib/python3.7/site-packages/wandb/sdk/lib/retry.py", line 102, in __call__
    result = self._call_fn(*args, **kwargs)
  File "/home/pxk/anaconda3/envs/cxy/lib/python3.7/site-packages/wandb/sdk/internal/internal_api.py", line 140, in execute
    return self.client.execute(*args, **kwargs)
  File "/home/pxk/anaconda3/envs/cxy/lib/python3.7/site-packages/wandb/vendor/gql-0.2.0/gql/client.py", line 52, in execute
    result = self._get_result(document, *args, **kwargs)
  File "/home/pxk/anaconda3/envs/cxy/lib/python3.7/site-packages/wandb/vendor/gql-0.2.0/gql/client.py", line 60, in _get_result
    return self.transport.execute(document, *args, **kwargs)
  File "/home/pxk/anaconda3/envs/cxy/lib/python3.7/site-packages/wandb/vendor/gql-0.2.0/gql/transport/requests.py", line 38, in execute
    request = requests.post(self.url, **post_args)
  File "/home/pxk/anaconda3/envs/cxy/lib/python3.7/site-packages/requests/api.py", line 117, in post
    return request('post', url, data=data, json=json, **kwargs)
  File "/home/pxk/anaconda3/envs/cxy/lib/python3.7/site-packages/requests/api.py", line 61, in request
    return session.request(method=method, url=url, **kwargs)
  File "/home/pxk/anaconda3/envs/cxy/lib/python3.7/site-packages/requests/sessions.py", line 529, in request
    resp = self.send(prep, **send_kwargs)
  File "/home/pxk/anaconda3/envs/cxy/lib/python3.7/site-packages/requests/sessions.py", line 645, in send
    r = adapter.send(request, **kwargs)
  File "/home/pxk/anaconda3/envs/cxy/lib/python3.7/site-packages/requests/adapters.py", line 517, in send
    raise SSLError(e, request=request)
requests.exceptions.SSLError: HTTPSConnectionPool(host='api.wandb.ai', port=443): Max retries exceeded with url: /graphql (Caused by SSLError(SSLError(1, '[SSL: KRB5_S_TKT_NYV] unexpected eof while reading (_ssl.c:1091)')))
2022-03-04 09:13:58,869 INFO    MainThread:3476583 [interface_shared.py:_communicate_run():313] couldn't get run from backend
2022-03-04 09:13:58,870 ERROR   MainThread:3476583 [wandb_init.py:init():601] backend process timed out
2022-03-04 09:13:58,870 ERROR   MainThread:3476583 [wandb_init.py:init():610] encountered error: Error communicating with wandb process
try: wandb.init(settings=wandb.Settings(start_method='fork'))
or:  wandb.init(settings=wandb.Settings(start_method='thread'))
For more info see: https://docs.wandb.ai/library/init#init-start-error
2022-03-04 09:14:08,698 WARNING MainThread:3476583 [wandb_init.py:init():972] interrupted
Traceback (most recent call last):
  File "/home/pxk/anaconda3/envs/cxy/lib/python3.7/site-packages/wandb/sdk/wandb_init.py", line 951, in init
    run = wi.init()
  File "/home/pxk/anaconda3/envs/cxy/lib/python3.7/site-packages/wandb/sdk/wandb_init.py", line 614, in init
    backend.cleanup()
  File "/home/pxk/anaconda3/envs/cxy/lib/python3.7/site-packages/wandb/sdk/backend/backend.py", line 250, in cleanup
    self.wandb_process.join()
  File "/home/pxk/anaconda3/envs/cxy/lib/python3.7/multiprocessing/process.py", line 140, in join
    res = self._popen.wait(timeout)
  File "/home/pxk/anaconda3/envs/cxy/lib/python3.7/multiprocessing/popen_fork.py", line 48, in wait
    return self.poll(os.WNOHANG if timeout == 0.0 else 0)
  File "/home/pxk/anaconda3/envs/cxy/lib/python3.7/multiprocessing/popen_fork.py", line 28, in poll
    pid, sts = os.waitpid(self.pid, flag)
KeyboardInterrupt
