2022-03-04 09:13:27,701 INFO    MainThread:3476736 [internal.py:wandb_internal():92] W&B internal server running at pid: 3476736, started at: 2022-03-04 09:13:27.701525
2022-03-04 09:13:27,702 DEBUG   HandlerThread:3476736 [handler.py:handle_request():131] handle_request: check_version
2022-03-04 09:13:27,703 DEBUG   SenderThread:3476736 [sender.py:send():235] send: header
2022-03-04 09:13:27,703 DEBUG   SenderThread:3476736 [sender.py:send_request():249] send_request: check_version
2022-03-04 09:13:27,703 INFO    WriterThread:3476736 [datastore.py:open_for_write():77] open: /home/pxk/CBREN/wandb/run-20220304_091327-22vdt3du/run-22vdt3du.wandb
2022-03-04 09:13:28,870 DEBUG   SenderThread:3476736 [sender.py:send():235] send: run
2022-03-04 09:13:35,917 ERROR   SenderThread:3476736 [retry.py:__call__():126] Retry attempt failed:
Traceback (most recent call last):
  File "/home/pxk/anaconda3/envs/cxy/lib/python3.7/site-packages/urllib3/connectionpool.py", line 700, in urlopen
    self._prepare_proxy(conn)
  File "/home/pxk/anaconda3/envs/cxy/lib/python3.7/site-packages/urllib3/connectionpool.py", line 994, in _prepare_proxy
    conn.connect()
  File "/home/pxk/anaconda3/envs/cxy/lib/python3.7/site-packages/urllib3/connection.py", line 426, in connect
    tls_in_tls=tls_in_tls,
  File "/home/pxk/anaconda3/envs/cxy/lib/python3.7/site-packages/urllib3/util/ssl_.py", line 450, in ssl_wrap_socket
    sock, context, tls_in_tls, server_hostname=server_hostname
  File "/home/pxk/anaconda3/envs/cxy/lib/python3.7/site-packages/urllib3/util/ssl_.py", line 493, in _ssl_wrap_socket_impl
    return ssl_context.wrap_socket(sock, server_hostname=server_hostname)
  File "/home/pxk/anaconda3/envs/cxy/lib/python3.7/ssl.py", line 423, in wrap_socket
    session=session
  File "/home/pxk/anaconda3/envs/cxy/lib/python3.7/ssl.py", line 870, in _create
    self.do_handshake()
  File "/home/pxk/anaconda3/envs/cxy/lib/python3.7/ssl.py", line 1139, in do_handshake
    self._sslobj.do_handshake()
ssl.SSLError: [SSL: KRB5_S_TKT_NYV] unexpected eof while reading (_ssl.c:1091)

During handling of the above exception, another exception occurred:

Traceback (most recent call last):
  File "/home/pxk/anaconda3/envs/cxy/lib/python3.7/site-packages/requests/adapters.py", line 450, in send
    timeout=timeout
  File "/home/pxk/anaconda3/envs/cxy/lib/python3.7/site-packages/urllib3/connectionpool.py", line 786, in urlopen
    method, url, error=e, _pool=self, _stacktrace=sys.exc_info()[2]
  File "/home/pxk/anaconda3/envs/cxy/lib/python3.7/site-packages/urllib3/util/retry.py", line 592, in increment
    raise MaxRetryError(_pool, url, error or ResponseError(cause))
urllib3.exceptions.MaxRetryError: HTTPSConnectionPool(host='api.wandb.ai', port=443): Max retries exceeded with url: /graphql (Caused by SSLError(SSLError(1, '[SSL: KRB5_S_TKT_NYV] unexpected eof while reading (_ssl.c:1091)')))

During handling of the above exception, another exception occurred:

Traceback (most recent call last):
  File "/home/pxk/anaconda3/envs/cxy/lib/python3.7/site-packages/wandb/sdk/lib/retry.py", line 102, in __call__
    result = self._call_fn(*args, **kwargs)
  File "/home/pxk/anaconda3/envs/cxy/lib/python3.7/site-packages/wandb/sdk/internal/internal_api.py", line 140, in execute
    return self.client.execute(*args, **kwargs)
  File "/home/pxk/anaconda3/envs/cxy/lib/python3.7/site-packages/wandb/vendor/gql-0.2.0/gql/client.py", line 52, in execute
    result = self._get_result(document, *args, **kwargs)
  File "/home/pxk/anaconda3/envs/cxy/lib/python3.7/site-packages/wandb/vendor/gql-0.2.0/gql/client.py", line 60, in _get_result
    return self.transport.execute(document, *args, **kwargs)
  File "/home/pxk/anaconda3/envs/cxy/lib/python3.7/site-packages/wandb/vendor/gql-0.2.0/gql/transport/requests.py", line 38, in execute
    request = requests.post(self.url, **post_args)
  File "/home/pxk/anaconda3/envs/cxy/lib/python3.7/site-packages/requests/api.py", line 117, in post
    return request('post', url, data=data, json=json, **kwargs)
  File "/home/pxk/anaconda3/envs/cxy/lib/python3.7/site-packages/requests/api.py", line 61, in request
    return session.request(method=method, url=url, **kwargs)
  File "/home/pxk/anaconda3/envs/cxy/lib/python3.7/site-packages/requests/sessions.py", line 529, in request
    resp = self.send(prep, **send_kwargs)
  File "/home/pxk/anaconda3/envs/cxy/lib/python3.7/site-packages/requests/sessions.py", line 645, in send
    r = adapter.send(request, **kwargs)
  File "/home/pxk/anaconda3/envs/cxy/lib/python3.7/site-packages/requests/adapters.py", line 517, in send
    raise SSLError(e, request=request)
requests.exceptions.SSLError: HTTPSConnectionPool(host='api.wandb.ai', port=443): Max retries exceeded with url: /graphql (Caused by SSLError(SSLError(1, '[SSL: KRB5_S_TKT_NYV] unexpected eof while reading (_ssl.c:1091)')))
2022-03-04 09:13:58,871 DEBUG   HandlerThread:3476736 [handler.py:handle_request():131] handle_request: shutdown
2022-03-04 09:13:58,872 INFO    HandlerThread:3476736 [handler.py:finish():739] shutting down handler
2022-03-04 09:13:58,882 INFO    WriterThread:3476736 [datastore.py:close():281] close: /home/pxk/CBREN/wandb/run-20220304_091327-22vdt3du/run-22vdt3du.wandb
2022-03-04 09:14:12,246 INFO    MainThread:3476736 [internal.py:handle_exit():79] Internal process exited
