2022-02-26 10:51:52,475 INFO    MainThread:690054 [internal.py:wandb_internal():92] W&B internal server running at pid: 690054, started at: 2022-02-26 10:51:52.475146
2022-02-26 10:51:52,480 DEBUG   HandlerThread:690054 [handler.py:handle_request():131] handle_request: check_version
2022-02-26 10:51:52,481 DEBUG   SenderThread:690054 [sender.py:send():235] send: header
2022-02-26 10:51:52,481 INFO    WriterThread:690054 [datastore.py:open_for_write():77] open: /home/pxk/CBREN/wandb/run-20220226_105151-31pkj01h/run-31pkj01h.wandb
2022-02-26 10:51:52,481 DEBUG   SenderThread:690054 [sender.py:send_request():249] send_request: check_version
2022-02-26 10:51:57,482 DEBUG   SenderThread:690054 [sender.py:send():235] send: run
2022-02-26 10:52:26,947 DEBUG   HandlerThread:690054 [handler.py:handle_request():131] handle_request: shutdown
2022-02-26 10:52:26,947 INFO    HandlerThread:690054 [handler.py:finish():739] shutting down handler
2022-02-26 10:52:27,944 INFO    WriterThread:690054 [datastore.py:close():281] close: /home/pxk/CBREN/wandb/run-20220226_105151-31pkj01h/run-31pkj01h.wandb
2022-02-26 10:52:31,151 ERROR   SenderThread:690054 [retry.py:__call__():126] Retry attempt failed:
Traceback (most recent call last):
  File "/home/pxk/anaconda3/envs/cxy/lib/python3.7/site-packages/urllib3/connection.py", line 175, in _new_conn
    (self._dns_host, self.port), self.timeout, **extra_kw
  File "/home/pxk/anaconda3/envs/cxy/lib/python3.7/site-packages/urllib3/util/connection.py", line 72, in create_connection
    for res in socket.getaddrinfo(host, port, family, socket.SOCK_STREAM):
  File "/home/pxk/anaconda3/envs/cxy/lib/python3.7/socket.py", line 752, in getaddrinfo
    for res in _socket.getaddrinfo(host, port, family, type, proto, flags):
socket.gaierror: [Errno -3] Temporary failure in name resolution

During handling of the above exception, another exception occurred:

Traceback (most recent call last):
  File "/home/pxk/anaconda3/envs/cxy/lib/python3.7/site-packages/urllib3/connectionpool.py", line 710, in urlopen
    chunked=chunked,
  File "/home/pxk/anaconda3/envs/cxy/lib/python3.7/site-packages/urllib3/connectionpool.py", line 386, in _make_request
    self._validate_conn(conn)
  File "/home/pxk/anaconda3/envs/cxy/lib/python3.7/site-packages/urllib3/connectionpool.py", line 1040, in _validate_conn
    conn.connect()
  File "/home/pxk/anaconda3/envs/cxy/lib/python3.7/site-packages/urllib3/connection.py", line 358, in connect
    conn = self._new_conn()
  File "/home/pxk/anaconda3/envs/cxy/lib/python3.7/site-packages/urllib3/connection.py", line 187, in _new_conn
    self, "Failed to establish a new connection: %s" % e
urllib3.exceptions.NewConnectionError: <urllib3.connection.HTTPSConnection object at 0x7ffb82a33110>: Failed to establish a new connection: [Errno -3] Temporary failure in name resolution

During handling of the above exception, another exception occurred:

Traceback (most recent call last):
  File "/home/pxk/anaconda3/envs/cxy/lib/python3.7/site-packages/requests/adapters.py", line 450, in send
    timeout=timeout
  File "/home/pxk/anaconda3/envs/cxy/lib/python3.7/site-packages/urllib3/connectionpool.py", line 786, in urlopen
    method, url, error=e, _pool=self, _stacktrace=sys.exc_info()[2]
  File "/home/pxk/anaconda3/envs/cxy/lib/python3.7/site-packages/urllib3/util/retry.py", line 592, in increment
    raise MaxRetryError(_pool, url, error or ResponseError(cause))
urllib3.exceptions.MaxRetryError: HTTPSConnectionPool(host='api.wandb.ai', port=443): Max retries exceeded with url: /graphql (Caused by NewConnectionError('<urllib3.connection.HTTPSConnection object at 0x7ffb82a33110>: Failed to establish a new connection: [Errno -3] Temporary failure in name resolution'))

During handling of the above exception, another exception occurred:

Traceback (most recent call last):
  File "/home/pxk/anaconda3/envs/cxy/lib/python3.7/site-packages/wandb/sdk/lib/retry.py", line 102, in __call__
    result = self._call_fn(*args, **kwargs)
  File "/home/pxk/anaconda3/envs/cxy/lib/python3.7/site-packages/wandb/sdk/internal/internal_api.py", line 140, in execute
    return self.client.execute(*args, **kwargs)
  File "/home/pxk/anaconda3/envs/cxy/lib/python3.7/site-packages/wandb/vendor/gql-0.2.0/gql/client.py", line 52, in execute
    result = self._get_result(document, *args, **kwargs)
  File "/home/pxk/anaconda3/envs/cxy/lib/python3.7/site-packages/wandb/vendor/gql-0.2.0/gql/client.py", line 60, in _get_result
    return self.transport.execute(document, *args, **kwargs)
  File "/home/pxk/anaconda3/envs/cxy/lib/python3.7/site-packages/wandb/vendor/gql-0.2.0/gql/transport/requests.py", line 38, in execute
    request = requests.post(self.url, **post_args)
  File "/home/pxk/anaconda3/envs/cxy/lib/python3.7/site-packages/requests/api.py", line 117, in post
    return request('post', url, data=data, json=json, **kwargs)
  File "/home/pxk/anaconda3/envs/cxy/lib/python3.7/site-packages/requests/api.py", line 61, in request
    return session.request(method=method, url=url, **kwargs)
  File "/home/pxk/anaconda3/envs/cxy/lib/python3.7/site-packages/requests/sessions.py", line 529, in request
    resp = self.send(prep, **send_kwargs)
  File "/home/pxk/anaconda3/envs/cxy/lib/python3.7/site-packages/requests/sessions.py", line 645, in send
    r = adapter.send(request, **kwargs)
  File "/home/pxk/anaconda3/envs/cxy/lib/python3.7/site-packages/requests/adapters.py", line 519, in send
    raise ConnectionError(e, request=request)
requests.exceptions.ConnectionError: HTTPSConnectionPool(host='api.wandb.ai', port=443): Max retries exceeded with url: /graphql (Caused by NewConnectionError('<urllib3.connection.HTTPSConnection object at 0x7ffb82a33110>: Failed to establish a new connection: [Errno -3] Temporary failure in name resolution'))
2022-02-26 10:54:39,428 INFO    MainThread:690054 [internal.py:handle_exit():79] Internal process exited
