2022-02-26 10:51:51,894 INFO    MainThread:689633 [wandb_setup.py:_flush():75] Loading settings from /home/pxk/.config/wandb/settings
2022-02-26 10:51:51,894 INFO    MainThread:689633 [wandb_setup.py:_flush():75] Loading settings from /home/pxk/CBREN/wandb/settings
2022-02-26 10:51:51,895 INFO    MainThread:689633 [wandb_setup.py:_flush():75] Loading settings from environment variables: {}
2022-02-26 10:51:51,895 INFO    MainThread:689633 [wandb_setup.py:_flush():75] Inferring run settings from compute environment: {'program_relpath': 'train_psnr_dct.py', 'program': 'train_psnr_dct.py'}
2022-02-26 10:51:51,895 INFO    MainThread:689633 [wandb_init.py:_log_setup():386] Logging user logs to /home/pxk/CBREN/wandb/run-20220226_105151-31pkj01h/logs/debug.log
2022-02-26 10:51:51,895 INFO    MainThread:689633 [wandb_init.py:_log_setup():387] Logging internal logs to /home/pxk/CBREN/wandb/run-20220226_105151-31pkj01h/logs/debug-internal.log
2022-02-26 10:51:51,895 INFO    MainThread:689633 [wandb_init.py:init():420] calling init triggers
2022-02-26 10:51:51,895 INFO    MainThread:689633 [wandb_init.py:init():427] wandb.init called with sweep_config: {}
config: {'lr_rate': 0.0001, 'epoch': 5000, 'batch_size': 16}
2022-02-26 10:51:51,895 INFO    MainThread:689633 [wandb_init.py:init():471] starting backend
2022-02-26 10:51:51,895 INFO    MainThread:689633 [backend.py:_multiprocessing_setup():101] multiprocessing start_methods=fork,spawn,forkserver, using: spawn
2022-02-26 10:51:51,906 INFO    MainThread:689633 [backend.py:ensure_launched():219] starting backend process...
2022-02-26 10:51:51,912 INFO    MainThread:689633 [backend.py:ensure_launched():225] started backend process with pid: 690054
2022-02-26 10:51:51,913 INFO    MainThread:689633 [wandb_init.py:init():480] backend started and connected
2022-02-26 10:51:51,916 INFO    MainThread:689633 [wandb_init.py:init():550] updated telemetry
2022-02-26 10:51:51,939 INFO    MainThread:689633 [wandb_init.py:init():581] communicating current version
2022-02-26 10:51:56,939 INFO    MainThread:689633 [wandb_init.py:init():596] communicating run to backend with 30 second timeout
2022-02-26 10:52:17,042 ERROR   Thread-1  :689633 [retry.py:__call__():126] Retry attempt failed:
Traceback (most recent call last):
  File "/home/pxk/anaconda3/envs/cxy/lib/python3.7/site-packages/urllib3/connection.py", line 175, in _new_conn
    (self._dns_host, self.port), self.timeout, **extra_kw
  File "/home/pxk/anaconda3/envs/cxy/lib/python3.7/site-packages/urllib3/util/connection.py", line 72, in create_connection
    for res in socket.getaddrinfo(host, port, family, socket.SOCK_STREAM):
  File "/home/pxk/anaconda3/envs/cxy/lib/python3.7/socket.py", line 752, in getaddrinfo
    for res in _socket.getaddrinfo(host, port, family, type, proto, flags):
socket.gaierror: [Errno -3] Temporary failure in name resolution

During handling of the above exception, another exception occurred:

Traceback (most recent call last):
  File "/home/pxk/anaconda3/envs/cxy/lib/python3.7/site-packages/urllib3/connectionpool.py", line 710, in urlopen
    chunked=chunked,
  File "/home/pxk/anaconda3/envs/cxy/lib/python3.7/site-packages/urllib3/connectionpool.py", line 386, in _make_request
    self._validate_conn(conn)
  File "/home/pxk/anaconda3/envs/cxy/lib/python3.7/site-packages/urllib3/connectionpool.py", line 1040, in _validate_conn
    conn.connect()
  File "/home/pxk/anaconda3/envs/cxy/lib/python3.7/site-packages/urllib3/connection.py", line 358, in connect
    conn = self._new_conn()
  File "/home/pxk/anaconda3/envs/cxy/lib/python3.7/site-packages/urllib3/connection.py", line 187, in _new_conn
    self, "Failed to establish a new connection: %s" % e
urllib3.exceptions.NewConnectionError: <urllib3.connection.HTTPSConnection object at 0x7fec680f3a90>: Failed to establish a new connection: [Errno -3] Temporary failure in name resolution

During handling of the above exception, another exception occurred:

Traceback (most recent call last):
  File "/home/pxk/anaconda3/envs/cxy/lib/python3.7/site-packages/requests/adapters.py", line 450, in send
    timeout=timeout
  File "/home/pxk/anaconda3/envs/cxy/lib/python3.7/site-packages/urllib3/connectionpool.py", line 786, in urlopen
    method, url, error=e, _pool=self, _stacktrace=sys.exc_info()[2]
  File "/home/pxk/anaconda3/envs/cxy/lib/python3.7/site-packages/urllib3/util/retry.py", line 592, in increment
    raise MaxRetryError(_pool, url, error or ResponseError(cause))
urllib3.exceptions.MaxRetryError: HTTPSConnectionPool(host='api.wandb.ai', port=443): Max retries exceeded with url: /graphql (Caused by NewConnectionError('<urllib3.connection.HTTPSConnection object at 0x7fec680f3a90>: Failed to establish a new connection: [Errno -3] Temporary failure in name resolution'))

During handling of the above exception, another exception occurred:

Traceback (most recent call last):
  File "/home/pxk/anaconda3/envs/cxy/lib/python3.7/site-packages/wandb/sdk/lib/retry.py", line 102, in __call__
    result = self._call_fn(*args, **kwargs)
  File "/home/pxk/anaconda3/envs/cxy/lib/python3.7/site-packages/wandb/sdk/internal/internal_api.py", line 140, in execute
    return self.client.execute(*args, **kwargs)
  File "/home/pxk/anaconda3/envs/cxy/lib/python3.7/site-packages/wandb/vendor/gql-0.2.0/gql/client.py", line 52, in execute
    result = self._get_result(document, *args, **kwargs)
  File "/home/pxk/anaconda3/envs/cxy/lib/python3.7/site-packages/wandb/vendor/gql-0.2.0/gql/client.py", line 60, in _get_result
    return self.transport.execute(document, *args, **kwargs)
  File "/home/pxk/anaconda3/envs/cxy/lib/python3.7/site-packages/wandb/vendor/gql-0.2.0/gql/transport/requests.py", line 38, in execute
    request = requests.post(self.url, **post_args)
  File "/home/pxk/anaconda3/envs/cxy/lib/python3.7/site-packages/requests/api.py", line 117, in post
    return request('post', url, data=data, json=json, **kwargs)
  File "/home/pxk/anaconda3/envs/cxy/lib/python3.7/site-packages/requests/api.py", line 61, in request
    return session.request(method=method, url=url, **kwargs)
  File "/home/pxk/anaconda3/envs/cxy/lib/python3.7/site-packages/requests/sessions.py", line 529, in request
    resp = self.send(prep, **send_kwargs)
  File "/home/pxk/anaconda3/envs/cxy/lib/python3.7/site-packages/requests/sessions.py", line 645, in send
    r = adapter.send(request, **kwargs)
  File "/home/pxk/anaconda3/envs/cxy/lib/python3.7/site-packages/requests/adapters.py", line 519, in send
    raise ConnectionError(e, request=request)
requests.exceptions.ConnectionError: HTTPSConnectionPool(host='api.wandb.ai', port=443): Max retries exceeded with url: /graphql (Caused by NewConnectionError('<urllib3.connection.HTTPSConnection object at 0x7fec680f3a90>: Failed to establish a new connection: [Errno -3] Temporary failure in name resolution'))
2022-02-26 10:52:26,940 INFO    MainThread:689633 [interface_shared.py:_communicate_run():313] couldn't get run from backend
2022-02-26 10:52:26,940 ERROR   MainThread:689633 [wandb_init.py:init():601] backend process timed out
2022-02-26 10:52:26,947 ERROR   MainThread:689633 [wandb_init.py:init():610] encountered error: Error communicating with wandb process
try: wandb.init(settings=wandb.Settings(start_method='fork'))
or:  wandb.init(settings=wandb.Settings(start_method='thread'))
For more info see: https://docs.wandb.ai/library/init#init-start-error
2022-02-26 10:53:01,150 WARNING MainThread:689633 [wandb_init.py:init():972] interrupted
Traceback (most recent call last):
  File "/home/pxk/anaconda3/envs/cxy/lib/python3.7/site-packages/wandb/sdk/wandb_init.py", line 951, in init
    run = wi.init()
  File "/home/pxk/anaconda3/envs/cxy/lib/python3.7/site-packages/wandb/sdk/wandb_init.py", line 614, in init
    backend.cleanup()
  File "/home/pxk/anaconda3/envs/cxy/lib/python3.7/site-packages/wandb/sdk/backend/backend.py", line 250, in cleanup
    self.wandb_process.join()
  File "/home/pxk/anaconda3/envs/cxy/lib/python3.7/multiprocessing/process.py", line 140, in join
    res = self._popen.wait(timeout)
  File "/home/pxk/anaconda3/envs/cxy/lib/python3.7/multiprocessing/popen_fork.py", line 48, in wait
    return self.poll(os.WNOHANG if timeout == 0.0 else 0)
  File "/home/pxk/anaconda3/envs/cxy/lib/python3.7/multiprocessing/popen_fork.py", line 28, in poll
    pid, sts = os.waitpid(self.pid, flag)
KeyboardInterrupt
