2022-03-04 09:15:41,853 INFO    MainThread:3479628 [internal.py:wandb_internal():92] W&B internal server running at pid: 3479628, started at: 2022-03-04 09:15:41.853282
2022-03-04 09:15:41,854 DEBUG   HandlerThread:3479628 [handler.py:handle_request():131] handle_request: check_version
2022-03-04 09:15:41,855 INFO    WriterThread:3479628 [datastore.py:open_for_write():77] open: /home/pxk/CBREN/wandb/run-20220304_091541-8jmeq5ov/run-8jmeq5ov.wandb
2022-03-04 09:15:41,855 DEBUG   SenderThread:3479628 [sender.py:send():235] send: header
2022-03-04 09:15:41,855 DEBUG   SenderThread:3479628 [sender.py:send_request():249] send_request: check_version
2022-03-04 09:15:42,657 DEBUG   SenderThread:3479628 [sender.py:send():235] send: run
2022-03-04 09:15:51,869 ERROR   SenderThread:3479628 [retry.py:__call__():126] Retry attempt failed:
Traceback (most recent call last):
  File "/home/pxk/anaconda3/envs/cxy/lib/python3.7/site-packages/urllib3/connection.py", line 175, in _new_conn
    (self._dns_host, self.port), self.timeout, **extra_kw
  File "/home/pxk/anaconda3/envs/cxy/lib/python3.7/site-packages/urllib3/util/connection.py", line 95, in create_connection
    raise err
  File "/home/pxk/anaconda3/envs/cxy/lib/python3.7/site-packages/urllib3/util/connection.py", line 85, in create_connection
    sock.connect(sa)
OSError: [Errno 113] No route to host

During handling of the above exception, another exception occurred:

Traceback (most recent call last):
  File "/home/pxk/anaconda3/envs/cxy/lib/python3.7/site-packages/urllib3/connectionpool.py", line 700, in urlopen
    self._prepare_proxy(conn)
  File "/home/pxk/anaconda3/envs/cxy/lib/python3.7/site-packages/urllib3/connectionpool.py", line 994, in _prepare_proxy
    conn.connect()
  File "/home/pxk/anaconda3/envs/cxy/lib/python3.7/site-packages/urllib3/connection.py", line 358, in connect
    conn = self._new_conn()
  File "/home/pxk/anaconda3/envs/cxy/lib/python3.7/site-packages/urllib3/connection.py", line 187, in _new_conn
    self, "Failed to establish a new connection: %s" % e
urllib3.exceptions.NewConnectionError: <urllib3.connection.HTTPSConnection object at 0x7f2b4cd91050>: Failed to establish a new connection: [Errno 113] No route to host

During handling of the above exception, another exception occurred:

Traceback (most recent call last):
  File "/home/pxk/anaconda3/envs/cxy/lib/python3.7/site-packages/requests/adapters.py", line 450, in send
    timeout=timeout
  File "/home/pxk/anaconda3/envs/cxy/lib/python3.7/site-packages/urllib3/connectionpool.py", line 786, in urlopen
    method, url, error=e, _pool=self, _stacktrace=sys.exc_info()[2]
  File "/home/pxk/anaconda3/envs/cxy/lib/python3.7/site-packages/urllib3/util/retry.py", line 592, in increment
    raise MaxRetryError(_pool, url, error or ResponseError(cause))
urllib3.exceptions.MaxRetryError: HTTPSConnectionPool(host='api.wandb.ai', port=443): Max retries exceeded with url: /graphql (Caused by ProxyError('Cannot connect to proxy.', NewConnectionError('<urllib3.connection.HTTPSConnection object at 0x7f2b4cd91050>: Failed to establish a new connection: [Errno 113] No route to host')))

During handling of the above exception, another exception occurred:

Traceback (most recent call last):
  File "/home/pxk/anaconda3/envs/cxy/lib/python3.7/site-packages/wandb/sdk/lib/retry.py", line 102, in __call__
    result = self._call_fn(*args, **kwargs)
  File "/home/pxk/anaconda3/envs/cxy/lib/python3.7/site-packages/wandb/sdk/internal/internal_api.py", line 140, in execute
    return self.client.execute(*args, **kwargs)
  File "/home/pxk/anaconda3/envs/cxy/lib/python3.7/site-packages/wandb/vendor/gql-0.2.0/gql/client.py", line 52, in execute
    result = self._get_result(document, *args, **kwargs)
  File "/home/pxk/anaconda3/envs/cxy/lib/python3.7/site-packages/wandb/vendor/gql-0.2.0/gql/client.py", line 60, in _get_result
    return self.transport.execute(document, *args, **kwargs)
  File "/home/pxk/anaconda3/envs/cxy/lib/python3.7/site-packages/wandb/vendor/gql-0.2.0/gql/transport/requests.py", line 38, in execute
    request = requests.post(self.url, **post_args)
  File "/home/pxk/anaconda3/envs/cxy/lib/python3.7/site-packages/requests/api.py", line 117, in post
    return request('post', url, data=data, json=json, **kwargs)
  File "/home/pxk/anaconda3/envs/cxy/lib/python3.7/site-packages/requests/api.py", line 61, in request
    return session.request(method=method, url=url, **kwargs)
  File "/home/pxk/anaconda3/envs/cxy/lib/python3.7/site-packages/requests/sessions.py", line 529, in request
    resp = self.send(prep, **send_kwargs)
  File "/home/pxk/anaconda3/envs/cxy/lib/python3.7/site-packages/requests/sessions.py", line 645, in send
    r = adapter.send(request, **kwargs)
  File "/home/pxk/anaconda3/envs/cxy/lib/python3.7/site-packages/requests/adapters.py", line 513, in send
    raise ProxyError(e, request=request)
requests.exceptions.ProxyError: HTTPSConnectionPool(host='api.wandb.ai', port=443): Max retries exceeded with url: /graphql (Caused by ProxyError('Cannot connect to proxy.', NewConnectionError('<urllib3.connection.HTTPSConnection object at 0x7f2b4cd91050>: Failed to establish a new connection: [Errno 113] No route to host')))
2022-03-04 09:16:12,658 DEBUG   HandlerThread:3479628 [handler.py:handle_request():131] handle_request: shutdown
2022-03-04 09:16:12,659 INFO    HandlerThread:3479628 [handler.py:finish():739] shutting down handler
2022-03-04 09:16:12,669 INFO    WriterThread:3479628 [datastore.py:close():281] close: /home/pxk/CBREN/wandb/run-20220304_091541-8jmeq5ov/run-8jmeq5ov.wandb
2022-03-04 09:19:38,085 INFO    MainThread:3479628 [internal.py:handle_exit():79] Internal process exited
