Namespace(batchSize=16, cuda=True, dataset='datasets/', lr=0.0001, momentum=0.9, nEpochs=5000, resume='', start_epoch=1, step=1000, test_path='dataset/test/', threads=16, validate_path='datasets/validate/', weight_decay=0)
===> Loading datasets
===> Building model
n_pyramids: 1 n_pyramid_cells: (3, 2, 1, 1, 1, 1)
===> Setting GPU
===> Setting Optimizer
===> Training
Epoch=1, lr=0.0001
===> Epoch[1](1/11): Loss: 0.5066961050
===> Epoch[1](2/11): Loss: 0.3794073462
===> Epoch[1](3/11): Loss: 0.4074614048
===> Epoch[1](4/11): Loss: 0.4057476223
===> Epoch[1](5/11): Loss: 0.3166005313
===> Epoch[1](6/11): Loss: 0.2777665854
Traceback (most recent call last):
  File "train_psnr_indication.py", line 331, in <module>
    main()
  File "train_psnr_indication.py", line 160, in main
    validate(model, optimizer, epoch)
  File "train_psnr_indication.py", line 289, in validate
    validate_set = get_validate_set()
  File "/home/pxk/CBREN/dataset.py", line 25, in get_validate_set
    return ValidateDataset(dir=root_path)
TypeError: __init__() got an unexpected keyword argument 'dir'
===> Epoch[1](7/11): Loss: 0.3337510824
===> Epoch[1](8/11): Loss: 0.3925874233
===> Epoch[1](9/11): Loss: 0.3957167566
===> Epoch[1](10/11): Loss: 0.3583220243
===> Epoch[1](11/11): Loss: 0.3481440544
|||||||||||||||||||||min_epoch_loss is 0.3747455396|||||||||||||||||||||
----Start Validate----