Namespace(batchSize=16, cuda=True, dataset='datasets/', lr=0.0001, momentum=0.9, nEpochs=2000, resume='', start_epoch=1, step=1000, test_path='dataset/test/', threads=16, validate_path='datasets/validate/', weight_decay=0)
===> Loading datasets
===> Building model
n_pyramids: 1 n_pyramid_cells: (3, 2, 1, 1, 1, 1)
===> Setting GPU
===> Setting Optimizer
===> Training
Epoch=1, lr=0.0001
===> Epoch[1](1/11): Loss: 0.3460117280
===> Epoch[1](2/11): Loss: 0.4635800719
===> Epoch[1](3/11): Loss: 0.4238824844
===> Epoch[1](4/11): Loss: 0.3808341026
===> Epoch[1](5/11): Loss: 0.2728789449
===> Epoch[1](6/11): Loss: 0.3504455090
===> Epoch[1](7/11): Loss: 0.3594118357
===> Epoch[1](8/11): Loss: 0.3160825372
===> Epoch[1](9/11): Loss: 0.3884567022
===> Epoch[1](10/11): Loss: 0.2640635073
===> Epoch[1](11/11): Loss: 0.3205731511
|||||||||||||||||||||min_epoch_loss is 0.3532927795|||||||||||||||||||||
----Start Validate----
Traceback (most recent call last):
  File "train_psnr_indication.py", line 314, in <module>
    main()
  File "train_psnr_indication.py", line 162, in main
    validate(model, optimizer, epoch)
  File "train_psnr_indication.py", line 279, in validate
    for iteration, batch in enumerate(validate_data_loader, 1):
NameError: name 'validate_data_loader' is not defined